<?xml version="1.0" ?>
<!-- =================================================================================== -->
<!-- |    This document was autogenerated by xacro from /home/daniel/rocket_ws/src/rocket_sim/models/rocket/rocket_model.xacro | -->
<!-- |    EDITING THIS FILE BY HAND IS NOT RECOMMENDED                                 | -->
<!-- =================================================================================== -->
<!-- Revolute-Revolute Manipulator -->
<robot name="rocket">
  <origin rpy="0 0 0" xyz="0 0 1"/>
  <!-- damping coefficient -->
  <!-- Import Rviz colors -->
  <!-- <xacro:include filename="$(find ros_robotics)/urdf/materials.xacro" /> -->
  <!--  Base station  -->
  <link name="base_station">
    <origin rpy="0 0 0" xyz="0 0 -0.4"/>
    <visual>
      <geometry>
        <box size="1 1 0.1"/>
      </geometry>
    </visual>
    <visual>
      <origin rpy="0 0 0" xyz="0 -0.5 1"/>
      <geometry>
        <box size="0.1 0.1 2"/>
      </geometry>
    </visual>
    <collision>
      <geometry>
        <box size="1 1 0.01"/>
      </geometry>
    </collision>
    <inertial>
      <mass value="5000"/>
      <origin xyz="0 0 0"/>
      <inertia ixx="421.70816464999996" ixy="0.0" ixz="0.0" iyy="421.70816464999996" iyz="0.0" izz="833.333"/>
    </inertial>
  </link>
  <joint name="moving_station_joint" type="prismatic">
    <parent link="base_station"/>
    <child link="moving_station"/>
    <origin rpy="0 0 0" xyz="0 -0.5 1.5"/>
    <axis xyz="0 0 1"/>
    <dynamics damping="0.01" friction="0.01"/>
    <limit effort="3000" lower="-0.5" upper="0.5" velocity="1.0"/>
  </joint>
  <link name="moving_station">
    <visual>
      <origin rpy="0 0 0" xyz="0 0 0"/>
      <geometry>
        <box size="0.15 0.15 0.2"/>
      </geometry>
    </visual>
    <!--  Attached rectangle to the moving part  -->
    <visual>
      <origin rpy="0 0 0" xyz="0 0.25 0"/>
      <geometry>
        <box size="0.1 0.5 0.1"/>
      </geometry>
    </visual>
    <collision>
      <origin rpy="0 0 0" xyz="0 0.25 0"/>
      <geometry>
        <box size="0.1 0.5 0.1"/>
      </geometry>
    </collision>
    <inertial>
      <mass value="20"/>
      <origin xyz="0 0 0"/>
      <inertia ixx="0.43333316" ixy="0.0" ixz="0.0" iyy="0.03333332000000001" iyz="0.0" izz="0.43333316"/>
    </inertial>
  </link>
  <joint name="station_to_rocket" type="revolute">
    <parent link="moving_station"/>
    <child link="base_link"/>
    <origin rpy="0 0 0" xyz="0 0.5 0"/>
    <axis xyz="0 1 0"/>
    <dynamics damping="0.03" friction="0.03"/>
    <limit effort="100000.0" lower="-1" upper="1" velocity="5"/>
  </joint>
  <!-- Rocket model -->
  <link name="base_link">
    <visual>
      <origin rpy="0 0 0" xyz="0 0 0.2"/>
      <geometry>
        <cylinder length="0.8" radius="0.15000000000000002"/>
      </geometry>
    </visual>
    <collision>
      <origin rpy="0 0 0" xyz="0 0 0.2"/>
      <geometry>
        <cylinder length="0.8" radius="0.15000000000000002"/>
      </geometry>
    </collision>
    <inertial>
      <mass value="10"/>
      <origin xyz="0 0 0"/>
      <inertia ixx="0.520833125" ixy="0.0" ixz="0.0" iyy="0.520833125" iyz="0.0" izz="0.104166625"/>
    </inertial>
  </link>
  <joint name="thruster_pitch_joint" type="revolute">
    <parent link="base_link"/>
    <child link="yaw_link"/>
    <origin rpy="0 0 0" xyz="0 0 -0.2"/>
    <axis xyz="1 0 0"/>
    <dynamics damping="100" friction="100"/>
    <limit effort="100.0" lower="-0.01" upper="0.01" velocity="0.5"/>
  </joint>
  <link name="yaw_link">
    <visual>
      <geometry>
        <box size="0.01 0.01 0.01"/>
      </geometry>
    </visual>
    <collision>
      <geometry>
        <box size="0.001 0.001 0.001"/>
      </geometry>
    </collision>
    <inertial>
      <mass value="0.3"/>
      <origin xyz="0 0 0"/>
      <inertia ixx="4.999998e-06" ixy="0.0" ixz="0.0" iyy="4.999998e-06" iyz="0.0" izz="4.999998e-06"/>
    </inertial>
  </link>
  <joint name="thruster_yaw_joint" type="revolute">
    <parent link="yaw_link"/>
    <child link="thruster"/>
    <origin rpy="0 0 0" xyz="0 0 0"/>
    <axis xyz="0 1 0"/>
    <dynamics damping="0.5" friction="0.5"/>
    <limit effort="10000.0" lower="-2" upper="2" velocity="5"/>
  </joint>
  <link name="thruster">
    <visual>
      <origin rpy="0 0 0" xyz="0 0 -0.1"/>
      <geometry>
        <cylinder length="0.2" radius="0.05"/>
      </geometry>
    </visual>
    <collision>
      <origin rpy="0 0 0" xyz="0 0 -0.1"/>
      <geometry>
        <cylinder length="0.2" radius="0.05"/>
      </geometry>
    </collision>
    <inertial>
      <mass value="0.3"/>
      <origin xyz="0 0 0"/>
      <inertia ixx="4.999998e-06" ixy="0.0" ixz="0.0" iyy="4.999998e-06" iyz="0.0" izz="4.999998e-06"/>
    </inertial>
  </link>
  <transmission name="tran1">
    <type>transmission_interface/SimpleTransmission</type>
    <joint name="thruster_pitch_joint">
      <hardwareInterface>hardware_interface/PositionJointInterface</hardwareInterface>
    </joint>
    <actuator name="motor1">
      <hardwareInterface>hardware_interface/PositionJointInterface</hardwareInterface>
      <mechanicalReduction>1</mechanicalReduction>
    </actuator>
  </transmission>
  <transmission name="tran2">
    <type>transmission_interface/SimpleTransmission</type>
    <joint name="thruster_yaw_joint">
      <hardwareInterface>hardware_interface/PositionJointInterface</hardwareInterface>
    </joint>
    <actuator name="motor2">
      <hardwareInterface>hardware_interface/PositionJointInterface</hardwareInterface>
      <mechanicalReduction>1</mechanicalReduction>
    </actuator>
  </transmission>
  <gazebo reference="base_station">
    <material>Gazebo/Grey</material>
  </gazebo>
  <gazebo reference="moving_station">
    <material>Gazebo/Blue</material>
  </gazebo>
  <gazebo>
    <plugin filename="libforce_plugin.so" name="force_plugin"/>
    <plugin filename="libgazebo_ros_imu.so" name="imu_plugin">
      <alwaysOn>true</alwaysOn>
      <bodyName>base_link</bodyName>
      <topicName>imu</topicName>
      <serviceName>imu_service</serviceName>
      <gaussianNoise>0.0</gaussianNoise>
      <updateRate>20.0</updateRate>
    </plugin>
    <plugin filename="libgazebo_ros_control.so" name="gazebo_ros_control">
      <robotNamespace>/rocket_sim</robotNamespace>
      <robotSimType>gazebo_ros_control/DefaultRobotHWSim</robotSimType>
    </plugin>
  </gazebo>
</robot>

